e2e/fixture.jsonl
{"bids":[["65000.10","0.50"],["64999.00","1.20"],["64990.00","2.00"]],"asks":[["65001.00","0.40"],["65002.50","0.80"],["65010.00","3.00"]]}
{"bids":[["65000.20","0.55"],["64999.00","1.10"]],"asks":[["65001.10","0.35"],["65002.50","0.70"]]}
{"bids":[["65000.50","0.70"],["64998.00","2.00"]],"asks":[["65001.50","0.20"],["65005.00","1.00"]]}
